Workbook

Sheet Dashboard
A1: FY2025 Expense Management Dashboard
A3: Prepared by: Finance Analyst | Data Source: Raw Data (250 transactions) | Use slicers below to filter by Region, Department, and Status
A4: Region Filter | B4: All | D4: Department Filter | E4: All | G4: Status Filter | H4: All | J4: Filtered Total Actual: | K4: =SUMPRODUCT((('Raw Data'!$D$2:$D$251=IF($B$4="All",'Raw Data'!$D$2:$D$251,$B$4)))*(('Raw Data'!$E$2:$E$251=IF($E$4="All",'Raw Data'!$E$2:$E$251,$E$4)))*(('Raw Data'!$J$2:$J$251=IF($H$4="All",'Raw Data'!$J$2:$J$251,$H$4)))*('Raw Data'!$H$2:$H$251)) -> 625940.85 | M4: Filtered Count: | N4: =SUMPRODUCT((('Raw Data'!$D$2:$D$251=IF($B$4="All",'Raw Data'!$D$2:$D$251,$B$4)))*(('Raw Data'!$E$2:$E$251=IF($E$4="All",'Raw Data'!$E$2:$E$251,$E$4)))*(('Raw Data'!$J$2:$J$251=IF($H$4="All",'Raw Data'!$J$2:$J$251,$H$4)))) -> 250
A5: Total Budget ($) | C5: Total Actual Spend ($) | E5: Variance % vs Budget | G5: Avg Transaction Value ($) | I5: Approval Rate % | K5: Total Transactions
A6: =SUM('Raw Data'!G2:G251) -> 612904.19 | C6: =SUM('Raw Data'!H2:H251) -> 625940.85 | E6: =(SUM('Raw Data'!H2:H251)-SUM('Raw Data'!G2:G251))/SUM('Raw Data'!G2:G251) -> 0.021270307 | G6: =AVERAGE('Raw Data'!H2:H251) -> 2503.7634 | I6: =COUNTIF('Raw Data'!J2:J251,"Approved")/COUNTA('Raw Data'!J2:J251) -> 0.7 | K6: =COUNTA('Raw Data'!A2:A251) -> 250
A9: Chart Data (linked)
A10: Region | B10: Budget | C10: Actual | E10: Month | F10: Budget | G10: Actual | I10: Category | J10: Actual
A11: =Calculations!A20 -> North America | B11: =Calculations!B20 -> 184317.11 | C11: =Calculations!C20 -> 191481.44 | E11: =Calculations!A36 -> Jan | F11: =Calculations!B36 -> 52019.5 | G11: =Calculations!C36 -> 53344.24 | I11: =Calculations!A51 -> Salaries | J11: =Calculations!C51 -> 294760.15
A12: =Calculations!A21 -> Europe | B12: =Calculations!B21 -> 121130.08 | C12: =Calculations!C21 -> 125348.36 | E12: =Calculations!A37 -> Feb | F12: =Calculations!B37 -> 51164.76 | G12: =Calculations!C37 -> 50163.01 | I12: =Calculations!A52 -> Software | J12: =Calculations!C52 -> 34275.54
A13: =Calculations!A22 -> Asia Pacific | B13: =Calculations!B22 -> 172142.56 | C13: =Calculations!C22 -> 172470.26 | E13: =Calculations!A38 -> Mar | F13: =Calculations!B38 -> 47008.12 | G13: =Calculations!C38 -> 48325.09 | I13: =Calculations!A53 -> Travel | J13: =Calculations!C53 -> 32826.98
A14: =Calculations!A23 -> Latin America | B14: =Calculations!B23 -> 135314.44 | C14: =Calculations!C23 -> 136640.79 | E14: =Calculations!A39 -> Apr | F14: =Calculations!B39 -> 52502.46 | G14: =Calculations!C39 -> 58772.79 | I14: =Calculations!A54 -> Office Supplies | J14: =Calculations!C54 -> 11324.12
E15: =Calculations!A40 -> May | F15: =Calculations!B40 -> 27105.71 | G15: =Calculations!C40 -> 29109.94 | I15: =Calculations!A55 -> Advertising | J15: =Calculations!C55 -> 92787.32
E16: =Calculations!A41 -> Jun | F16: =Calculations!B41 -> 42943.98 | G16: =Calculations!C41 -> 42340.5 | I16: =Calculations!A56 -> Utilities | J16: =Calculations!C56 -> 20839.79
E17: =Calculations!A42 -> Jul | F17: =Calculations!B42 -> 41685.16 | G17: =Calculations!C42 -> 41118.07 | I17: =Calculations!A57 -> Consulting | J17: =Calculations!C57 -> 110865.67
E18: =Calculations!A43 -> Aug | F18: =Calculations!B43 -> 90401.78 | G18: =Calculations!C43 -> 94734.38 | I18: =Calculations!A58 -> Training | J18: =Calculations!C58 -> 28261.28
E19: =Calculations!A44 -> Sep | F19: =Calculations!B44 -> 34057.21 | G19: =Calculations!C44 -> 31909.58
E20: =Calculations!A45 -> Oct | F20: =Calculations!B45 -> 49872.18 | G20: =Calculations!C45 -> 52438.26
E21: =Calculations!A46 -> Nov | F21: =Calculations!B46 -> 46134.32 | G21: =Calculations!C46 -> 42898.58
E22: =Calculations!A47 -> Dec | F22: =Calculations!B47 -> 78009.01 | G22: =Calculations!C47 -> 80786.41
A24: Department | B24: Budget | C24: Actual | E24: Status | F24: Count
A25: =Calculations!A27 -> Sales | B25: =Calculations!B27 -> 124332.03 | C25: =Calculations!C27 -> 131249.18 | E25: Approved | F25: =COUNTIF('Raw Data'!$J$2:$J$251,$E25) -> 175
A26: =Calculations!A28 -> Marketing | B26: =Calculations!B28 -> 75052.35 | C26: =Calculations!C28 -> 81528.6 | E26: Pending | F26: =COUNTIF('Raw Data'!$J$2:$J$251,$E26) -> 52
A27: =Calculations!A29 -> Operations | B27: =Calculations!B29 -> 75092.01 | C27: =Calculations!C29 -> 76443.04 | E27: Rejected | F27: =COUNTIF('Raw Data'!$J$2:$J$251,$E27) -> 23
A28: =Calculations!A30 -> IT | B28: =Calculations!B30 -> 109255.17 | C28: =Calculations!C30 -> 108944.32
A29: =Calculations!A31 -> HR | B29: =Calculations!B31 -> 134917.12 | C29: =Calculations!C31 -> 132945.81
A30: =Calculations!A32 -> Finance | B30: =Calculations!B32 -> 94255.51 | C30: =Calculations!C32 -> 94829.9

Sheet Raw Data
A1: Transaction ID | B1: Date | C1: Month | D1: Region | E1: Department | F1: Category | G1: Budgeted Amount | H1: Actual Amount | I1: Variance | J1: Status | K1: Employee Count
A2: TXN-1001 | B2: 45985 | C2: =TEXT(B2,"mmm") -> Nov | D2: North America | E2: Sales | F2: Advertising | G2: 2869.13 | H2: 2352.02 | I2: =H2-G2 -> -517.11 | J2: Approved | K2: 35
A3: TXN-1002 | B3: 45702 | C3: =TEXT(B3,"mmm") -> Feb | D3: Latin America | E3: Sales | F3: Salaries | G3: 6773.28 | H3: 5867.9 | I3: =H3-G3 -> -905.38 | J3: Approved | K3: 36
A4: TXN-1003 | B4: 45759 | C4: =TEXT(B4,"mmm") -> Apr | D4: Latin America | E4: Marketing | F4: Training | G4: 675.75 | H4: 780.3 | I4: =H4-G4 -> 104.55 | J4: Approved | K4: 11
A5: TXN-1004 | B5: 46015 | C5: =TEXT(B5,"mmm") -> Dec | D5: Latin America | E5: Operations | F5: Advertising | G5: 2044.66 | H5: 2512.08 | I5: =H5-G5 -> 467.42 | J5: Approved | K5: 6
A6: TXN-1005 | B6: 45852 | C6: =TEXT(B6,"mmm") -> Jul | D6: North America | E6: Operations | F6: Utilities | G6: 853.26 | H6: 984.29 | I6: =H6-G6 -> 131.03 | J6: Pending | K6: 35
A7: TXN-1006 | B7: 45721 | C7: =TEXT(B7,"mmm") -> Mar | D7: Latin America | E7: Sales | F7: Advertising | G7: 2617.49 | H7: 2772.6 | I7: =H7-G7 -> 155.11 | J7: Pending | K7: 37
A8: TXN-1007 | B8: 45756 | C8: =TEXT(B8,"mmm") -> Apr | D8: North America | E8: Sales | F8: Office Supplies | G8: 417.18 | H8: 518.39 | I8: =H8-G8 -> 101.21 | J8: Pending | K8: 7
A9: TXN-1008 | B9: 45852 | C9: =TEXT(B9,"mmm") -> Jul | D9: Asia Pacific | E9: IT | F9: Utilities | G9: 595.93 | H9: 552.81 | I9: =H9-G9 -> -43.12 | J9: Approved | K9: 45
A10: TXN-1009 | B10: 46007 | C10: =TEXT(B10,"mmm") -> Dec | D10: North America | E10: HR | F10: Travel | G10: 1152.63 | H10: 1005.56 | I10: =H10-G10 -> -147.07 | J10: Approved | K10: 18
A11: TXN-1010 | B11: 45985 | C11: =TEXT(B11,"mmm") -> Nov | D11: Europe | E11: Finance | F11: Utilities | G11: 844.35 | H11: 960.87 | I11: =H11-G11 -> 116.52 | J11: Approved | K11: 3
A12: TXN-1011 | B12: 45819 | C12: =TEXT(B12,"mmm") -> Jun | D12: Latin America | E12: Operations | F12: Software | G12: 1004.08 | H12: 1226.44 | I12: =H12-G12 -> 222.36 | J12: Pending | K12: 21
A13: TXN-1012 | B13: 45766 | C13: =TEXT(B13,"mmm") -> Apr | D13: Latin America | E13: IT | F13: Training | G13: 569.5 | H13: 466.88 | I13: =H13-G13 -> -102.62 | J13: Pending | K13: 35
... A251: TXN-1250 | B251: 45927 | C251: =TEXT(B251,"mmm") -> Sep | D251: Latin America | E251: Operations | F251: Travel | G251: 829.16 | H251: 842.89 | I251: =H251-G251 -> 13.73 | J251: Approved | K251: 44

Sheet Calculations
A1: Financial Calculations & Summary Analysis
A2: All figures pull directly from the Raw Data table (green = cross-sheet links)
A4: 1. Overall Budget vs Actual Summary
A5: Metric | B5: Value
A6: Total Budgeted Amount | B6: =SUM('Raw Data'!G2:G251) -> 612904.19
A7: Total Actual Amount | B7: =SUM('Raw Data'!H2:H251) -> 625940.85
A8: Total Variance (Actual - Budget) | B8: =B7-B6 -> 13036.66
A9: Variance % | B9: =B8/B6 -> 0.021270307
A10: Average Transaction (Actual) | B10: =AVERAGE('Raw Data'!H2:H251) -> 2503.7634
A11: Number of Transactions | B11: =COUNTA('Raw Data'!A2:A251) -> 250
A12: Approved Transactions | B12: =COUNTIF('Raw Data'!J2:J251,"Approved") -> 175
A13: Approval Rate % | B13: =B11/B10 -> 0.09984969
A14: Total Employee Count Covered | B14: =SUM('Raw Data'!K2:K251) -> 5686
A15: Highest Single Actual Expense | B15: =MAX('Raw Data'!H2:H251) -> 15269.47
A16: Lowest Single Actual Expense | B16: =MIN('Raw Data'!H2:H251) -> 209.37
A18: 2. Summary by Region
A19: Region | B19: Total Budget | C19: Total Actual | D19: Variance | E19: Variance %
A20: North America | B20: =SUMIF('Raw Data'!$D$2:$D$251,$A20,'Raw Data'!$G$2:$G$251) -> 184317.11 | C20: =SUMIF('Raw Data'!$D$2:$D$251,$A20,'Raw Data'!$H$2:$H$251) -> 191481.44 | D20: =C20-B20 -> 7164.33 | E20: =D20/B20 -> 0.038869587
A21: Europe | B21: =SUMIF('Raw Data'!$D$2:$D$251,$A21,'Raw Data'!$G$2:$G$251) -> 121130.08 | C21: =SUMIF('Raw Data'!$D$2:$D$251,$A21,'Raw Data'!$H$2:$H$251) -> 125348.36 | D21: =C21-B21 -> 4218.28 | E21: =D21/B21 -> 0.034824381
A22: Asia Pacific | B22: =SUMIF('Raw Data'!$D$2:$D$251,$A22,'Raw Data'!$G$2:$G$251) -> 172142.56 | C22: =SUMIF('Raw Data'!$D$2:$D$251,$A22,'Raw Data'!$H$2:$H$251) -> 172470.26 | D22: =C22-B22 -> 327.7 | E22: =D22/B22 -> 0.0019036547
A23: Latin America | B23: =SUMIF('Raw Data'!$D$2:$D$251,$A23,'Raw Data'!$G$2:$G$251) -> 135314.44 | C23: =SUMIF('Raw Data'!$D$2:$D$251,$A23,'Raw Data'!$H$2:$H$251) -> 136640.79 | D23: =C23-B23 -> 1326.35 | E23: =D23/B23 -> 0.0098019842
A25: 3. Summary by Department
A26: Department | B26: Total Budget | C26: Total Actual | D26: Variance | E26: Variance %
A27: Sales | B27: =SUMIF('Raw Data'!$E$2:$E$251,$A27,'Raw Data'!$G$2:$G$251) -> 124332.03 | C27: =SUMIF('Raw Data'!$E$2:$E$251,$A27,'Raw Data'!$H$2:$H$251) -> 131249.18 | D27: =C27-B27 -> 6917.15 | E27: =D27/B27 -> 0.055634497
A28: Marketing | B28: =SUMIF('Raw Data'!$E$2:$E$251,$A28,'Raw Data'!$G$2:$G$251) -> 75052.35 | C28: =SUMIF('Raw Data'!$E$2:$E$251,$A28,'Raw Data'!$H$2:$H$251) -> 81528.6 | D28: =C28-B28 -> 6476.25 | E28: =D28/B28 -> 0.08628977
A29: Operations | B29: =SUMIF('Raw Data'!$E$2:$E$251,$A29,'Raw Data'!$G$2:$G$251) -> 75092.01 | C29: =SUMIF('Raw Data'!$E$2:$E$251,$A29,'Raw Data'!$H$2:$H$251) -> 76443.04 | D29: =C29-B29 -> 1351.03 | E29: =D29/B29 -> 0.017991661
A30: IT | B30: =SUMIF('Raw Data'!$E$2:$E$251,$A30,'Raw Data'!$G$2:$G$251) -> 109255.17 | C30: =SUMIF('Raw Data'!$E$2:$E$251,$A30,'Raw Data'!$H$2:$H$251) -> 108944.32 | D30: =C30-B30 -> -310.85 | E30: =D30/B30 -> -0.0028451743
A31: HR | B31: =SUMIF('Raw Data'!$E$2:$E$251,$A31,'Raw Data'!$G$2:$G$251) -> 134917.12 | C31: =SUMIF('Raw Data'!$E$2:$E$251,$A31,'Raw Data'!$H$2:$H$251) -> 132945.81 | D31: =C31-B31 -> -1971.31 | E31: =D31/B31 -> -0.014611267
A32: Finance | B32: =SUMIF('Raw Data'!$E$2:$E$251,$A32,'Raw Data'!$G$2:$G$251) -> 94255.51 | C32: =SUMIF('Raw Data'!$E$2:$E$251,$A32,'Raw Data'!$H$2:$H$251) -> 94829.9 | D32: =C32-B32 -> 574.39 | E32: =D32/B32 -> 0.0060939673
A34: 4. Summary by Month
A35: Month | B35: Total Budget | C35: Total Actual | D35: Variance | E35: Variance %
A36: Jan | B36: =SUMIF('Raw Data'!$C$2:$C$251,$A36,'Raw Data'!$G$2:$G$251) -> 52019.5 | C36: =SUMIF('Raw Data'!$C$2:$C$251,$A36,'Raw Data'!$H$2:$H$251) -> 53344.24 | D36: =C36-B36 -> 1324.74 | E36: =D36/B36 -> 0.025466219
A37: Feb | B37: =SUMIF('Raw Data'!$C$2:$C$251,$A37,'Raw Data'!$G$2:$G$251) -> 51164.76 | C37: =SUMIF('Raw Data'!$C$2:$C$251,$A37,'Raw Data'!$H$2:$H$251) -> 50163.01 | D37: =C37-B37 -> -1001.75 | E37: =D37/B37 -> -0.019578905
A38: Mar | B38: =SUMIF('Raw Data'!$C$2:$C$251,$A38,'Raw Data'!$G$2:$G$251) -> 47008.12 | C38: =SUMIF('Raw Data'!$C$2:$C$251,$A38,'Raw Data'!$H$2:$H$251) -> 48325.09 | D38: =C38-B38 -> 1316.97 | E38: =D38/B38 -> 0.028015798
A39: Apr | B39: =SUMIF('Raw Data'!$C$2:$C$251,$A39,'Raw Data'!$G$2:$G$251) -> 52502.46 | C39: =SUMIF('Raw Data'!$C$2:$C$251,$A39,'Raw Data'!$H$2:$H$251) -> 58772.79 | D39: =C39-B39 -> 6270.33 | E39: =D39/B39 -> 0.11942926
A40: May | B40: =SUMIF('Raw Data'!$C$2:$C$251,$A40,'Raw Data'!$G$2:$G$251) -> 27105.71 | C40: =SUMIF('Raw Data'!$C$2:$C$251,$A40,'Raw Data'!$H$2:$H$251) -> 29109.94 | D40: =C40-B40 -> 2004.23 | E40: =D40/B40 -> 0.073941247
A41: Jun | B41: =SUMIF('Raw Data'!$C$2:$C$251,$A41,'Raw Data'!$G$2:$G$251) -> 42943.98 | C41: =SUMIF('Raw Data'!$C$2:$C$251,$A41,'Raw Data'!$H$2:$H$251) -> 42340.5 | D41: =C41-B41 -> -603.48 | E41: =D41/B41 -> -0.014052726
A42: Jul | B42: =SUMIF('Raw Data'!$C$2:$C$251,$A42,'Raw Data'!$G$2:$G$251) -> 41685.16 | C42: =SUMIF('Raw Data'!$C$2:$C$251,$A42,'Raw Data'!$H$2:$H$251) -> 41118.07 | D42: =C42-B42 -> -567.09 | E42: =D42/B42 -> -0.013604122
A43: Aug | B43: =SUMIF('Raw Data'!$C$2:$C$251,$A43,'Raw Data'!$G$2:$G$251) -> 90401.78 | C43: =SUMIF('Raw Data'!$C$2:$C$251,$A43,'Raw Data'!$H$2:$H$251) -> 94734.38 | D43: =C43-B43 -> 4332.6 | E43: =D43/B43 -> 0.047926047
A44: Sep | B44: =SUMIF('Raw Data'!$C$2:$C$251,$A44,'Raw Data'!$G$2:$G$251) -> 34057.21 | C44: =SUMIF('Raw Data'!$C$2:$C$251,$A44,'Raw Data'!$H$2:$H$251) -> 31909.58 | D44: =C44-B44 -> -2147.63 | E44: =D44/B44 -> -0.063059481
...

Sheet Pivot Tables
A1: Pivot Tables — Region x Department Analysis
A2: Cross-tabulated views built with SUMIFS against the Raw Data table
A4: Pivot 1: Actual Amount by Region (rows) and Department (columns)
A5: Region | B5: Sales | C5: Marketing | D5: Operations | E5: IT | F5: HR | G5: Finance | H5: Grand Total
A6: North America | B6: =SUMIFS('Raw Data'!$H$2:$H$251,'Raw Data'!$D$2:$D$251,$A6,'Raw Data'!$E$2:$E$251,B$5) -> 46209.81 | C6: =SUMIFS('Raw Data'!$H$2:$H$251,'Raw Data'!$D$2:$D$251,$A6,'Raw Data'!$E$2:$E$251,C$5) -> 21218.17 | D6: =SUMIFS('Raw Data'!$H$2:$H$251,'Raw Data'!$D$2:$D$251,$A6,'Raw Data'!$E$2:$E$251,D$5) -> 25740.15 | E6: =SUMIFS('Raw Data'!$H$2:$H$251,'Raw Data'!$D$2:$D$251,$A6,'Raw Data'!$E$2:$E$251,E$5) -> 18829.69 | F6: =SUMIFS('Raw Data'!$H$2:$H$251,'Raw Data'!$D$2:$D$251,$A6,'Raw Data'!$E$2:$E$251,F$5) -> 27916.19 | G6: =SUMIFS('Raw Data'!$H$2:$H$251,'Raw Data'!$D$2:$D$251,$A6,'Raw Data'!$E$2:$E$251,G$5) -> 51567.43 | H6: =SUM(B6:G6) -> 191481.44
A7: Europe | B7: =SUMIFS('Raw Data'!$H$2:$H$251,'Raw Data'!$D$2:$D$251,$A7,'Raw Data'!$E$2:$E$251,B$5) -> 10140.8 | C7: =SUMIFS('Raw Data'!$H$2:$H$251,'Raw Data'!$D$2:$D$251,$A7,'Raw Data'!$E$2:$E$251,C$5) -> 29551.43 | D7: =SUMIFS('Raw Data'!$H$2:$H$251,'Raw Data'!$D$2:$D$251,$A7,'Raw Data'!$E$2:$E$251,D$5) -> 12144.68 | E7: =SUMIFS('Raw Data'!$H$2:$H$251,'Raw Data'!$D$2:$D$251,$A7,'Raw Data'!$E$2:$E$251,E$5) -> 27304.72 | F7: =SUMIFS('Raw Data'!$H$2:$H$251,'Raw Data'!$D$2:$D$251,$A7,'Raw Data'!$E$2:$E$251,F$5) -> 25782.67 | G7: =SUMIFS('Raw Data'!$H$2:$H$251,'Raw Data'!$D$2:$D$251,$A7,'Raw Data'!$E$2:$E$251,G$5) -> 20424.06 | H7: =SUM(B7:G7) -> 125348.36
A8: Asia Pacific | B8: =SUMIFS('Raw Data'!$H$2:$H$251,'Raw Data'!$D$2:$D$251,$A8,'Raw Data'!$E$2:$E$251,B$5) -> 45211.29 | C8: =SUMIFS('Raw Data'!$H$2:$H$251,'Raw Data'!$D$2:$D$251,$A8,'Raw Data'!$E$2:$E$251,C$5) -> 23351.78 | D8: =SUMIFS('Raw Data'!$H$2:$H$251,'Raw Data'!$D$2:$D$251,$A8,'Raw Data'!$E$2:$E$251,D$5) -> 9662.06 | E8: =SUMIFS('Raw Data'!$H$2:$H$251,'Raw Data'!$D$2:$D$251,$A8,'Raw Data'!$E$2:$E$251,E$5) -> 51414.45 | F8: =SUMIFS('Raw Data'!$H$2:$H$251,'Raw Data'!$D$2:$D$251,$A8,'Raw Data'!$E$2:$E$251,F$5) -> 24326.79 | G8: =SUMIFS('Raw Data'!$H$2:$H$251,'Raw Data'!$D$2:$D$251,$A8,'Raw Data'!$E$2:$E$251,G$5) -> 18503.89 | H8: =SUM(B8:G8) -> 172470.26
A9: Latin America | B9: =SUMIFS('Raw Data'!$H$2:$H$251,'Raw Data'!$D$2:$D$251,$A9,'Raw Data'!$E$2:$E$251,B$5) -> 29687.28 | C9: =SUMIFS('Raw Data'!$H$2:$H$251,'Raw Data'!$D$2:$D$251,$A9,'Raw Data'!$E$2:$E$251,C$5) -> 7407.22 | D9: =SUMIFS('Raw Data'!$H$2:$H$251,'Raw Data'!$D$2:$D$251,$A9,'Raw Data'!$E$2:$E$251,D$5) -> 28896.15 | E9: =SUMIFS('Raw Data'!$H$2:$H$251,'Raw Data'!$D$2:$D$251,$A9,'Raw Data'!$E$2:$E$251,E$5) -> 11395.46 | F9: =SUMIFS('Raw Data'!$H$2:$H$251,'Raw Data'!$D$2:$D$251,$A9,'Raw Data'!$E$2:$E$251,F$5) -> 54920.16 | G9: =SUMIFS('Raw Data'!$H$2:$H$251,'Raw Data'!$D$2:$D$251,$A9,'Raw Data'!$E$2:$E$251,G$5) -> 4334.52 | H9: =SUM(B9:G9) -> 136640.79
A10: Grand Total | B10: =SUM(B6:B9) -> 131249.18 | C10: =SUM(C6:C9) -> 81528.6 | D10: =SUM(D6:D9) -> 76443.04 | E10: =SUM(E6:E9) -> 108944.32 | F10: =SUM(F6:F9) -> 132945.81 | G10: =SUM(G6:G9) -> 94829.9 | H10: =SUM(H6:H9) -> 625940.85
A13: Pivot 2: Count of Transactions by Category (rows) and Status (columns)
A14: Category | B14: Approved | C14: Pending | D14: Rejected | E14: Grand Total
A15: Salaries | B15: =COUNTIFS('Raw Data'!$F$2:$F$251,$A15,'Raw Data'!$J$2:$J$251,B$14) -> 20 | C15: =COUNTIFS('Raw Data'!$F$2:$F$251,$A15,'Raw Data'!$J$2:$J$251,C$14) -> 5 | D15: =COUNTIFS('Raw Data'!$F$2:$F$251,$A15,'Raw Data'!$J$2:$J$251,D$14) -> 7 | E15: =SUM(B15:D15) -> 32
A16: Software | B16: =COUNTIFS('Raw Data'!$F$2:$F$251,$A16,'Raw Data'!$J$2:$J$251,B$14) -> 17 | C16: =COUNTIFS('Raw Data'!$F$2:$F$251,$A16,'Raw Data'!$J$2:$J$251,C$14) -> 6 | D16: =COUNTIFS('Raw Data'!$F$2:$F$251,$A16,'Raw Data'!$J$2:$J$251,D$14) -> 3 | E16: =SUM(B16:D16) -> 26
A17: Travel | B17: =COUNTIFS('Raw Data'!$F$2:$F$251,$A17,'Raw Data'!$J$2:$J$251,B$14) -> 21 | C17: =COUNTIFS('Raw Data'!$F$2:$F$251,$A17,'Raw Data'!$J$2:$J$251,C$14) -> 7 | D17: =COUNTIFS('Raw Data'!$F$2:$F$251,$A17,'Raw Data'!$J$2:$J$251,D$14) -> 4 | E17: =SUM(B17:D17) -> 32
A18: Office Supplies | B18: =COUNTIFS('Raw Data'!$F$2:$F$251,$A18,'Raw Data'!$J$2:$J$251,B$14) -> 24 | C18: =COUNTIFS('Raw Data'!$F$2:$F$251,$A18,'Raw Data'!$J$2:$J$251,C$14) -> 6 | D18: =COUNTIFS('Raw Data'!$F$2:$F$251,$A18,'Raw Data'!$J$2:$J$251,D$14) -> 2 | E18: =SUM(B18:D18) -> 32
A19: Advertising | B19: =COUNTIFS('Raw Data'!$F$2:$F$251,$A19,'Raw Data'!$J$2:$J$251,B$14) -> 21 | C19: =COUNTIFS('Raw Data'!$F$2:$F$251,$A19,'Raw Data'!$J$2:$J$251,C$14) -> 6 | D19: =COUNTIFS('Raw Data'!$F$2:$F$251,$A19,'Raw Data'!$J$2:$J$251,D$14) -> 4 | E19: =SUM(B19:D19) -> 31
A20: Utilities | B20: =COUNTIFS('Raw Data'!$F$2:$F$251,$A20,'Raw Data'!$J$2:$J$251,B$14) -> 21 | C20: =COUNTIFS('Raw Data'!$F$2:$F$251,$A20,'Raw Data'!$J$2:$J$251,C$14) -> 6 | D20: =COUNTIFS('Raw Data'!$F$2:$F$251,$A20,'Raw Data'!$J$2:$J$251,D$14) -> 2 | E20: =SUM(B20:D20) -> 29
A21: Consulting | B21: =COUNTIFS('Raw Data'!$F$2:$F$251,$A21,'Raw Data'!$J$2:$J$251,B$14) -> 21 | C21: =COUNTIFS('Raw Data'!$F$2:$F$251,$A21,'Raw Data'!$J$2:$J$251,C$14) -> 9 | D21: =COUNTIFS('Raw Data'!$F$2:$F$251,$A21,'Raw Data'!$J$2:$J$251,D$14) -> 0 | E21: =SUM(B21:D21) -> 30
A22: Training | B22: =COUNTIFS('Raw Data'!$F$2:$F$251,$A22,'Raw Data'!$J$2:$J$251,B$14) -> 30 | C22: =COUNTIFS('Raw Data'!$F$2:$F$251,$A22,'Raw Data'!$J$2:$J$251,C$14) -> 7 | D22: =COUNTIFS('Raw Data'!$F$2:$F$251,$A22,'Raw Data'!$J$2:$J$251,D$14) -> 1 | E22: =SUM(B22:D22) -> 38
A23: Grand Total | B23: =SUM(B15:B22) -> 175 | C23: =SUM(C15:C22) -> 52 | D23: =SUM(D15:D22) -> 23 | E23: =SUM(E15:E22) -> 250
A26: Pivot 3: Variance (Actual - Budget) by Month (rows) and Region (columns)
A27: Month | B27: North America | C27: Europe | D27: Asia Pacific | E27: Latin America | F27: Grand Total
A28: Jan | B28: =SUMIFS('Raw Data'!$I$2:$I$251,'Raw Data'!$C$2:$C$251,$A28,'Raw Data'!$D$2:$D$251,B$27) -> 684.93 | C28: =SUMIFS('Raw Data'!$I$2:$I$251,'Raw Data'!$C$2:$C$251,$A28,'Raw Data'!$D$2:$D$251,C$27) -> -1257.2 | D28: =SUMIFS('Raw Data'!$I$2:$I$251,'Raw Data'!$C$2:$C$251,$A28,'Raw Data'!$D$2:$D$251,D$27) -> 2001.93 | E28: =SUMIFS('Raw Data'!$I$2:$I$251,'Raw Data'!$C$2:$C$251,$A28,'Raw Data'!$D$2:$D$251,E$27) -> -104.92 | F28: =SUM(B28:E28) -> 1324.74
A29: Feb | B29: =SUMIFS('Raw Data'!$I$2:$I$251,'Raw Data'!$C$2:$C$251,$A29,'Raw Data'!$D$2:$D$251,B$27) -> 667.49 | C29: =SUMIFS('Raw Data'!$I$2:$I$251,'Raw Data'!$C$2:$C$251,$A29,'Raw Data'!$D$2:$D$251,C$27) -> -497.36 | D29: =SUMIFS('Raw Data'!$I$2:$I$251,'Raw Data'!$C$2:$C$251,$A29,'Raw Data'!$D$2:$D$251,D$27) -> -333.57 | E29: =SUMIFS('Raw Data'!$I$2:$I$251,'Raw Data'!$C$2:$C$251,$A29,'Raw Data'!$D$2:$D$251,E$27) -> -838.31 | F29: =SUM(B29:E29) -> -1001.75
A30: Mar | B30: =SUMIFS('Raw Data'!$I$2:$I$251,'Raw Data'!$C$2:$C$251,$A30,'Raw Data'!$D$2:$D$251,B$27) -> -687.43 | C30: =SUMIFS('Raw Data'!$I$2:$I$251,'Raw Data'!$C$2:$C$251,$A30,'Raw Data'!$D$2:$D$251,C$27) -> 1352.82 | D30: =SUMIFS('Raw Data'!$I$2:$I$251,'Raw Data'!$C$2:$C$251,$A30,'Raw Data'!$D$2:$D$251,D$27) -> 480.91 | E30: =SUMIFS('Raw Data'!$I$2:$I$251,'Raw Data'!$C$2:$C$251,$A30,'Raw Data'!$D$2:$D$251,E$27) -> 170.67 | F30: =SUM(B30:E30) -> 1316.97
A31: Apr | B31: =SUMIFS('Raw Data'!$I$2:$I$251,'Raw Data'!$C$2:$C$251,$A31,'Raw Data'!$D$2:$D$251,B$27) -> 2702.55 | C31: =SUMIFS('Raw Data'!$I$2:$I$251,'Raw Data'!$C$2:$C$251,$A31,'Raw Data'!$D$2:$D$251,C$27) -> 2826.55 | D31: =SUMIFS('Raw Data'!$I$2:$I$251,'Raw Data'!$C$2:$C$251,$A31,'Raw Data'!$D$2:$D$251,D$27) -> -389.73 | E31: =SUMIFS('Raw Data'!$I$2:$I$251,'Raw Data'!$C$2:$C$251,$A31,'Raw Data'!$D$2:$D$251,E$27) -> 1130.96 | F31: =SUM(B31:E31) -> 6270.33
A32: May | B32: =SUMIFS('Raw Data'!$I$2:$I$251,'Raw Data'!$C$2:$C$251,$A32,'Raw Data'!$D$2:$D$251,B$27) -> 762.59 | C32: =SUMIFS('Raw Data'!$I$2:$I$251,'Raw Data'!$C$2:$C$251,$A32,'Raw Data'!$D$2:$D$251,C$27) -> 213.01 | D32: =SUMIFS('Raw Data'!$I$2:$I$251,'Raw Data'!$C$2:$C$251,$A32,'Raw Data'!$D$2:$D$251,D$27) -> 22.16 | E32: =SUMIFS('Raw Data'!$I$2:$I$251,'Raw Data'!$C$2:$C$251,$A32,'Raw Data'!$D$2:$D$251,E$27) -> 1006.47 | F32: =SUM(B32:E32) -> 2004.23
A33: Jun | B33: =SUMIFS('Raw Data'!$I$2:$I$251,'Raw Data'!$C$2:$C$251,$A33,'Raw Data'!$D$2:$D$251,B$27) -> 369.92 | C33: =SUMIFS('Raw Data'!$I$2:$I$251,'Raw Data'!$C$2:$C$251,$A33,'Raw Data'!$D$2:$D$251,C$27) -> -224.33 | D33: =SUMIFS('Raw Data'!$I$2:$I$251,'Raw Data'!$C$2:$C$251,$A33,'Raw Data'!$D$2:$D$251,D$27) -> -110.81 | E33: =SUMIFS('Raw Data'!$I$2:$I$251,'Raw Data'!$C$2:$C$251,$A33,'Raw Data'!$D$2:$D$251,E$27) -> -638.26 | F33: =SUM(B33:E33) -> -603.48
A34: Jul | B34: =SUMIFS('Raw Data'!$I$2:$I$251,'Raw Data'!$C$2:$C$251,$A34,'Raw Data'!$D$2:$D$251,B$27) -> -2121.41 | C34: =SUMIFS('Raw Data'!$I$2:$I$251,'Raw Data'!$C$2:$C$251,$A34,'Raw Data'!$D$2:$D$251,C$27) -> 13.48 | D34: =SUMIFS('Raw Data'!$I$2:$I$251,'Raw Data'!$C$2:$C$251,$A34,'Raw Data'!$D$2:$D$251,D$27) -> 1384.56 | E34: =SUMIFS('Raw Data'!$I$2:$I$251,'Raw Data'!$C$2:$C$251,$A34,'Raw Data'!$D$2:$D$251,E$27) -> 156.28 | F34: =SUM(B34:E34) -> -567.09
A35: Aug | B35: =SUMIFS('Raw Data'!$I$2:$I$251,'Raw Data'!$C$2:$C$251,$A35,'Raw Data'!$D$2:$D$251,B$27) -> -42.76 | C35: =SUMIFS('Raw Data'!$I$2:$I$251,'Raw Data'!$C$2:$C$251,$A35,'Raw Data'!$D$2:$D$251,C$27) -> 436.53 | D35: =SUMIFS('Raw Data'!$I$2:$I$251,'Raw Data'!$C$2:$C$251,$A35,'Raw Data'!$D$2:$D$251,D$27) -> 3009.02 | E35: =SUMIFS('Raw Data'!$I$2:$I$251,'Raw Data'!$C$2:$C$251,$A35,'Raw Data'!$D$2:$D$251,E$27) -> 929.81 | F35: =SUM(B35:E35) -> 4332.6
A36: Sep | B36: =SUMIFS('Raw Data'!$I$2:$I$251,'Raw Data'!$C$2:$C$251,$A36,'Raw Data'!$D$2:$D$251,B$27) -> 61.99 | C36: =SUMIFS('Raw Data'!$I$2:$I$251,'Raw Data'!$C$2:$C$251,$A36,'Raw Data'!$D$2:$D$251,C$27) -> -73.12 | D36: =SUMIFS('Raw Data'!$I$2:$I$251,'Raw Data'!$C$2:$C$251,$A36,'Raw Data'!$D$2:$D$251,D$27) -> -1066.43 | E36: =SUMIFS('Raw Data'!$I$2:$I$251,'Raw Data'!$C$2:$C$251,$A36,'Raw Data'!$D$2:$D$251,E$27) -> -1070.07 | F36: =SUM(B36:E36) -> -2147.63
A37: Oct | B37: =SUMIFS('Raw Data'!$I$2:$I$251,'Raw Data'!$C$2:$C$251,$A37,'Raw Data'!$D$2:$D$251,B$27) -> 2598.48 | C37: =SUMIFS('Raw Data'!$I$2:$I$251,'Raw Data'!$C$2:$C$251,$A37,'Raw Data'!$D$2:$D$251,C$27) -> -877.32 | D37: =SUMIFS('Raw Data'!$I$2:$I$251,'Raw Data'!$C$2:$C$251,$A37,'Raw Data'!$D$2:$D$251,D$27) -> -250.44 | E37: =SUMIFS('Raw Data'!$I$2:$I$251,'Raw Data'!$C$2:$C$251,$A37,'Raw Data'!$D$2:$D$251,E$27) -> 1095.36 | F37: =SUM(B37:E37) -> 2566.08
A38: Nov | B38: =SUMIFS('Raw Data'!$I$2:$I$251,'Raw Data'!$C$2:$C$251,$A38,'Raw Data'!$D$2:$D$251,B$27) -> -48.9 | C38: =SUMIFS('Raw Data'!$I$2:$I$251,'Raw Data'!$C$2:$C$251,$A38,'Raw Data'!$D$2:$D$251,C$27) -> -199.35 | D38: =SUMIFS('Raw Data'!$I$2:$I$251,'Raw Data'!$C$2:$C$251,$A38,'Raw Data'!$D$2:$D$251,D$27) -> -2964.9 | E38: =SUMIFS('Raw Data'!$I$2:$I$251,'Raw Data'!$C$2:$C$251,$A38,'Raw Data'!$D$2:$D$251,E$27) -> -22.59 | F38: =SUM(B38:E38) -> -3235.74
A39: Dec | B39: =SUMIFS('Raw Data'!$I$2:$I$251,'Raw Data'!$C$2:$C$251,$A39,'Raw Data'!$D$2:$D$251,B$27) -> 2216.88 | C39: =SUMIFS('Raw Data'!$I$2:$I$251,'Raw Data'!$C$2:$C$251,$A39,'Raw Data'!$D$2:$D$251,C$27) -> 2504.57 | D39: =SUMIFS('Raw Data'!$I$2:$I$251,'Raw Data'!$C$2:$C$251,$A39,'Raw Data'!$D$2:$D$251,D$27) -> -1455 | E39: =SUMIFS('Raw Data'!$I$2:$I$251,'Raw Data'!$C$2:$C$251,$A39,'Raw Data'!$D$2:$D$251,E$27) -> -489.05 | F39: =SUM(B39:E39) -> 2777.4
A40: Grand Total | B40: =SUM(B28:B39) -> 7164.33 | C40: =SUM(C28:C39) -> 4218.28 | D40: =SUM(D28:D39) -> 327.7 | E40: =SUM(E28:E39) -> 1326.35 | F40: =SUM(F28:F39) -> 13036.66

Sheet Lists
A1: All | B1: All | C1: All
A2: North America | B2: Sales | C2: Approved
A3: Europe | B3: Marketing | C3: Pending
A4: Asia Pacific | B4: Operations | C4: Rejected
A5: Latin America | B5: IT
B6: HR
B7: Finance
